Workbook
Name Loan_BaseCurves: '3 Market'!$B$59
Name Loan_C01_Discount: '2 Cases'!$B$9
Name Loan_C01_Fair0: '4 Build'!$B$49
Name Loan_C01_FairRate0: '5 Results'!$D$7
Name Loan_C01_Index: '2 Cases'!$D$8
Name Loan_C01_Instrument: '4 Build'!$B$37
Name Loan_C01_Net: '5 Results'!$C$7
Name Loan_C01_Pricer: '4 Build'!$B$43
Name Loan_C01_PV: '5 Results'!$B$7
Name Loan_C01_Rate: '2 Cases'!$B$8
Name Loan_C01_Repayment: '2 Cases'!$F$8
Name Loan_C01_Result: '4 Build'!$B$46
Name Loan_C01_Trade: '4 Build'!$B$40
Name Loan_C02_Discount: '2 Cases'!$B$19
Name Loan_C02_Fair0: '4 Build'!$B$69
Name Loan_C02_FairRate0: '5 Results'!$D$8
Name Loan_C02_Index: '2 Cases'!$D$18
Name Loan_C02_Instrument: '4 Build'!$B$57
Name Loan_C02_Net: '5 Results'!$C$8
Name Loan_C02_Pricer: '4 Build'!$B$63
Name Loan_C02_PV: '5 Results'!$B$8
Name Loan_C02_Rate: '2 Cases'!$B$18
Name Loan_C02_Repayment: '2 Cases'!$F$18
Name Loan_C02_Result: '4 Build'!$B$66
Name Loan_C02_Trade: '4 Build'!$B$60
Name Loan_C03_Discount: '2 Cases'!$B$29
Name Loan_C03_Fair0: '4 Build'!$B$92
Name Loan_C03_FairRate0: '5 Results'!$D$9
Name Loan_C03_Index: '2 Cases'!$D$28
Name Loan_C03_Instrument: '4 Build'!$B$80
Name Loan_C03_Net: '5 Results'!$C$9
Name Loan_C03_Options: '4 Build'!$B$77
Name Loan_C03_Pricer: '4 Build'!$B$86
Name Loan_C03_PV: '5 Results'!$B$9
Name Loan_C03_Rate: '2 Cases'!$B$28
Name Loan_C03_Repayment: '2 Cases'!$F$28
Name Loan_C03_Result: '4 Build'!$B$89
Name Loan_C03_Settings: '2 Cases'!$A$31:$B$32
Name Loan_C03_Trade: '4 Build'!$B$83
Name Loan_C04_Discount: '2 Cases'!$B$39
Name Loan_C04_Fair0: '4 Build'!$B$115
Name Loan_C04_FairRate0: '5 Results'!$D$10
Name Loan_C04_Index: '2 Cases'!$D$38
Name Loan_C04_Instrument: '4 Build'!$B$103
Name Loan_C04_Net: '5 Results'!$C$10
Name Loan_C04_Options: '4 Build'!$B$100
Name Loan_C04_Pricer: '4 Build'!$B$109
Name Loan_C04_PV: '5 Results'!$B$10
Name Loan_C04_Rate: '2 Cases'!$B$38
Name Loan_C04_Repayment: '2 Cases'!$F$38
Name Loan_C04_Result: '4 Build'!$B$112
Name Loan_C04_Settings: '2 Cases'!$A$41:$B$42
Name Loan_C04_Trade: '4 Build'!$B$106
Name Loan_C05_Coupons: '2 Cases'!$D$51:$F$53
Name Loan_C05_Discount: '2 Cases'!$B$49
Name Loan_C05_Fair0: '4 Build'!$B$135
Name Loan_C05_Fair1: '4 Build'!$B$138
Name Loan_C05_FairRate0: '5 Results'!$D$11
Name Loan_C05_FairRate1: '5 Results'!$E$11
Name Loan_C05_Index: '2 Cases'!$D$48

Sheet Start Here
A1: Loans · compare one change at a time
A3: Start with the French loan. Compare repayment, floating coupons, prepayment, credit and funding, then inspect stepped schedules.
A6: Before you start: load quantsupport.xll in 64-bit Windows Excel, then press Ctrl+Alt+F9. Results are blank until Excel calculates. Dates are ISO text; enter 4% as 0.04.
A9: Follow the numbered tabs from left to right
A10: 1 | B10: 1 Inputs | D10: Review shared loan terms and position direction.
A11: 2 | B11: 2 Cases | D11: Edit one case's coupon, settings or schedule in its own block.
A12: 3 | B12: 3 Market | D12: Review ordinary projection, discount, funding and credit curves.
A13: 4 | B13: 4 Build | D13: Follow the native construction and pricing steps.
A14: 5 | B14: 5 Results | D14: Compare all cases; select one for the detail sheets.
A15: 6 | B15: 6 Cashflows | D15: Inspect receipts for the selected case.
A16: 7 | B16: 7 Risk | D16: Inspect risk for the same selected case.
A17: 8 | B17: 8 Layouts | D17: Compare transpose and header options on a small curve table.
A20: Cell colours
A21: Blue · edit | D21: Assumptions and choices you can change.
A22: Green · read | D22: Financial results calculated by the add-in.
A23: Grey · build | D23: Object references on the Build tab. Each step shows its Excel formula below.
A25: Try this first
A26: 1. Compare French, Bullet and 25% balloon on Results.
A27: 2. Compare French with Funded fixed: only the discount policy changes.
A28: 3. Choose Stepped then floating on Results; inspect its three fair-rate targets, Cashflows and Risk.
A30: Use Ctrl+A after a function name for parameter help. Inline hints use the optional Excel-DNA IntelliSense companion. The example assumptions are illustrative; tables and results use the native Rust pricers.

Sheet 1 Inputs
A1: Contract and position inputs
A2: Shared inputs apply to all cases. Blue cells are editable; each case's specific terms are on the next tab.
A4: ← Start Here | C4: Next → 2 Cases
A6: Parameter | B6: Value | C6: Meaning
A7: Valuation date | B7: 2026-02-24 | C7: Valuation at origination supports the fair-rate solves.
A8: Principal (EUR) | B8: 250000 | C8: Contractual principal; the trade does not override it.
A9: Default fixed coupon | B9: 0.06 | C9: Used by the fixed-rate cases unless overridden.
A10: Default floating spread | B10: 0.01 | C10: Spread over EURIBOR12m.
A11: Start date | B11: 2026-02-24 | C11: Contractual origination date.
A12: Maturity date | B12: 2056-02-24 | C12: Thirty-year teaching example.
A13: Payment frequency | B13: Monthly | C13: Case schedule counts refer to payment periods.
A14: Day counter | B14: Actual360 | C14: Contractual accrual and amortization convention.
A15: Currency | B15: EUR | C15: These market assumptions are configured in EUR.
A16: Position side | B16: Receive | C16: Lender receipts are positive; Pay reverses the direction.
A20: Requested measure | B20: What the result contains
A21: Value | B21: Monetary present value
A22: Cashflows | B22: Resolved payments and receipts
A23: Sensitivities | B23: Raw derivatives per unit market input
A27: Policy currency | B27: Ordinary discount index
A28: EUR | B28: ESTR
A29: EUR | B29: FUNDING

Sheet 2 Cases
A1: Case inputs · one block per agreement
A2: Each block keeps its contractual settings and coupon schedule together. Discount-curve choice selects a pricer policy; it is never passed to the instrument.
A4: ← Start Here | F4: Next → 3 Market
A6: 01. French
A7: Baseline monthly amortization.
A8: Coupon / spread | B8: =Loan_FixedRate | C8: Projection index | E8: Repayment | F8: French
A9: Pricing discount curve | B9: ESTR
A11: Contract settings: native defaults. | D11: Coupon schedule: use the scalar rate / spread and projection index above.
A14: See this case's results →
A16: 02. Bullet
A17: Repay all principal at maturity.
A18: Coupon / spread | B18: =Loan_FixedRate | C18: Projection index | E18: Repayment | F18: Bullet
A19: Pricing discount curve | B19: ESTR
A21: Contract settings: native defaults. | D21: Coupon schedule: use the scalar rate / spread and projection index above.
A24: See this case's results →
A26: 03. 25% balloon
A27: Reserve one quarter of principal for maturity.
A28: Coupon / spread | B28: =Loan_FixedRate | C28: Projection index | E28: Repayment | F28: Balloon
A29: Pricing discount curve | B29: ESTR
A31: Setting | B31: Value | D31: Coupon schedule: use the scalar rate / spread and projection index above.
A32: Balloon fraction | B32: 0.25
A34: See this case's results →
A36: 04. Floating
A37: EURIBOR12m plus a spread; principal is agreed at 5%.
A38: Coupon / spread | B38: =Loan_FloatingSpread | C38: Projection index | D38: EURIBOR12m | E38: Repayment | F38: French
A39: Pricing discount curve | B39: ESTR
A41: Setting | B41: Value | D41: Coupon schedule: use the scalar rate / spread and projection index above.
A42: Amortization rate | B42: 0.05
A44: See this case's results →
A46: 05. 5-year introductory fixed
A47: Fixed for 60 payments, then floating through maturity.
A48: Coupon / spread | B48: =E52 | C48: Projection index | D48: =IF(F52="","",F52) | E48: Repayment | F48: French
A49: Pricing discount curve | B49: ESTR
A51: Contract settings: native defaults. | D51: Periods | E51: Rate / spread | F51: Market index
D52: 60 | E52: 0.04
E53: =Loan_FloatingSpread | F53: EURIBOR12m
D56: Edit this schedule; the scalar above follows its first row. Blank index = fixed; blank final count fills maturity. Fair-rate targets follow segment order.
A58: See this case's results →
A60: 06. Bounded floating
A61: Bounded projected coupons; fair rate is not supported.
...

Sheet 3 Market
A1: Market assumptions and curve construction
A2: Edit the blue rates. The steps below the input tables construct ordinary curves from those cells.
A4: ← Start Here | D4: Next → 4 Build
A6: Pillar | B6: ESTR zero | C6: EURIBOR12m zero | D6: Treasury spread
A7: 0D | B7: 0.03 | C7: 0.04 | D7: 0.005
A8: 5Y | B8: 0.03 | C8: 0.037 | D8: 0.01
A9: 10Y | B9: 0.032 | C9: 0.04 | D9: 0.011
A10: 30Y | B10: 0.034 | C10: 0.0415 | D10: 0.014
A11: 35Y | B11: 0.035 | C11: 0.0415 | D11: 0.015
A13: These are illustrative continuous zero rates on Actual360. FUNDING is an ordinary composite curve: EURIBOR12m discount factors × treasury-spread discount factors.
A17: Borrower CDS quote | B17: Annual spread
A18: Cds_BORROWER_EUR_1Y | B18: 0.005
A19: Cds_BORROWER_EUR_3Y | B19: 0.007
A20: Cds_BORROWER_EUR_5Y | B20: 0.009
A21: Cds_BORROWER_EUR_10Y | B21: 0.011
A22: Cds_BORROWER_EUR_20Y | B22: 0.014
A23: Cds_BORROWER_EUR_30Y | B23: 0.016
A24: Cds_BORROWER_EUR_35Y | B24: 0.017
A27: Borrower recovery | B27: 0.4 | C27: Fraction recovered on borrower default.
A31: Construction step | B31: Object reference | C31: Why it is needed
A32: 1. Create quote store | B32: {=_xll.QS.QUOTES.CREATE("Loan.Quotes",Loan_ValuationDate)} | C32: Sets the valuation date for the market.
A33: =SUBSTITUTE(_xlfn.FORMULATEXT(B32),",",", ") -> =QS.QUOTES.CREATE("Loan.Quotes", Loan_ValuationDate)
A35: 2.1 Load CDS quote | B35: {=_xll.QS.QUOTES.SET(Loan_InitialQuotes,'3 Market'!A18,'3 Market'!B18,,)} | C35: Each update consumes the preceding store revision.
A36: =SUBSTITUTE(_xlfn.FORMULATEXT(B35),",",", ") -> =QS.QUOTES.SET(Loan_InitialQuotes, '3 Market'!A18, '3 Market'!B18, , )
A38: 2.2 Load CDS quote | B38: {=_xll.QS.QUOTES.SET(Loan_CreditQuote1,'3 Market'!A19,'3 Market'!B19,,)} | C38: Each update consumes the preceding store revision.
A39: =SUBSTITUTE(_xlfn.FORMULATEXT(B38),",",", ") -> =QS.QUOTES.SET(Loan_CreditQuote1, '3 Market'!A19, '3 Market'!B19, , )
A41: 2.3 Load CDS quote | B41: {=_xll.QS.QUOTES.SET(Loan_CreditQuote2,'3 Market'!A20,'3 Market'!B20,,)} | C41: Each update consumes the preceding store revision.
A42: =SUBSTITUTE(_xlfn.FORMULATEXT(B41),",",", ") -> =QS.QUOTES.SET(Loan_CreditQuote2, '3 Market'!A20, '3 Market'!B20, , )
A44: 2.4 Load CDS quote | B44: {=_xll.QS.QUOTES.SET(Loan_CreditQuote3,'3 Market'!A21,'3 Market'!B21,,)} | C44: Each update consumes the preceding store revision.
A45: =SUBSTITUTE(_xlfn.FORMULATEXT(B44),",",", ") -> =QS.QUOTES.SET(Loan_CreditQuote3, '3 Market'!A21, '3 Market'!B21, , )
A47: 2.5 Load CDS quote | B47: {=_xll.QS.QUOTES.SET(Loan_CreditQuote4,'3 Market'!A22,'3 Market'!B22,,)} | C47: Each update consumes the preceding store revision.
A48: =SUBSTITUTE(_xlfn.FORMULATEXT(B47),",",", ") -> =QS.QUOTES.SET(Loan_CreditQuote4, '3 Market'!A22, '3 Market'!B22, , )
A50: 2.6 Load CDS quote | B50: {=_xll.QS.QUOTES.SET(Loan_CreditQuote5,'3 Market'!A23,'3 Market'!B23,,)} | C50: Each update consumes the preceding store revision.
A51: =SUBSTITUTE(_xlfn.FORMULATEXT(B50),",",", ") -> =QS.QUOTES.SET(Loan_CreditQuote5, '3 Market'!A23, '3 Market'!B23, , )
A53: 2.7 Load CDS quote | B53: {=_xll.QS.QUOTES.SET(Loan_CreditQuote6,'3 Market'!A24,'3 Market'!B24,,)} | C53: Each update consumes the preceding store revision.
A54: =SUBSTITUTE(_xlfn.FORMULATEXT(B53),",",", ") -> =QS.QUOTES.SET(Loan_CreditQuote6, '3 Market'!A24, '3 Market'!B24, , )
A56: 3. Create curve configurations | B56: {=_xll.QS.CURVE.CONFIGS.CREATE("Loan.Curves")} | C56: Curve construction choices are separate from contract terms.
A57: =SUBSTITUTE(_xlfn.FORMULATEXT(B56),",",", ") -> =QS.CURVE.CONFIGS.CREATE("Loan.Curves")
A59: 4. Configure ESTR | B59: {=_xll.QS.CURVE.CONFIGS.ADD.ZERO(Loan_InitialCurves,"ESTR","Actual360","Linear",TRUE,Loan_Pillars,Loan_ZeroRates,"Continuous","Annual")} | C59: The context builds this curve from the blue input range.
A60: =SUBSTITUTE(_xlfn.FORMULATEXT(B59),",",", ") -> =QS.CURVE.CONFIGS.ADD.ZERO(Loan_InitialCurves, "ESTR", "Actual360", "Linear", TRUE, Loan_Pillars, Loan_ZeroRates, "Continuous", "Annual")
...

Sheet 4 Build
A1: Build and evaluate the loan agreements
A2: Shared context and pricers come first. Each case then follows instrument → trade → pricer selection → evaluation. Use the links on Results to jump directly to a case.
A4: ← Start Here | C4: Next → 5 Results
A6: Step | B6: Object reference | C6: Purpose
A7: 1. Initialize pricing context | B7: {=_xll.QS.CONTEXT.FROM.COMPONENTS("Loan.Context",Loan_Quotes,Loan_Curves,Loan_Credit,,,,,,,,,"EUR","ESTR","Mid")} | C7: Constructs the projection, discount, funding and credit curves.
A8: =SUBSTITUTE(_xlfn.FORMULATEXT(B7),",",", ") -> =QS.CONTEXT.FROM.COMPONENTS("Loan.Context", Loan_Quotes, Loan_Curves, Loan_Credit, , , , , , , , , "EUR", "ESTR", "Mid")
A10: 2. ESTR discount policy | B10: {=_xll.QS.DISCOUNT.POLICY.FIXED.INCOME("Loan.RiskFreePolicy",Loan_RiskFreeCurrency,Loan_RiskFreeIndex)} | C10: Maps EUR to an ordinary market curve.
A11: =SUBSTITUTE(_xlfn.FORMULATEXT(B10),",",", ") -> =QS.DISCOUNT.POLICY.FIXED.INCOME("Loan.RiskFreePolicy", Loan_RiskFreeCurrency, Loan_RiskFreeIndex)
A13: 3. ESTR loan pricer | B13: {=_xll.QS.PRICER.CREATE("Loan.RiskFreePricer","LoanPricer",Loan_RiskFreePolicy)} | C13: Same native LoanPricer, with an explicit policy.
A14: =SUBSTITUTE(_xlfn.FORMULATEXT(B13),",",", ") -> =QS.PRICER.CREATE("Loan.RiskFreePricer", "LoanPricer", Loan_RiskFreePolicy)
A16: 4. FUNDING discount policy | B16: {=_xll.QS.DISCOUNT.POLICY.FIXED.INCOME("Loan.FundingPolicy",Loan_FundingCurrency,Loan_FundingIndex)} | C16: Maps EUR to an ordinary market curve.
A17: =SUBSTITUTE(_xlfn.FORMULATEXT(B16),",",", ") -> =QS.DISCOUNT.POLICY.FIXED.INCOME("Loan.FundingPolicy", Loan_FundingCurrency, Loan_FundingIndex)
A19: 5. FUNDING loan pricer | B19: {=_xll.QS.PRICER.CREATE("Loan.FundingPricer","LoanPricer",Loan_FundingPolicy)} | C19: Same native LoanPricer, with an explicit policy.
A20: =SUBSTITUTE(_xlfn.FORMULATEXT(B19),",",", ") -> =QS.PRICER.CREATE("Loan.FundingPricer", "LoanPricer", Loan_FundingPolicy)
A22: 6. Get ESTR for layout examples | B22: {=_xll.QS.CURVE.GET(Loan_Context,"ESTR")} | C22: A small five-node table for the layout lesson.
A23: =SUBSTITUTE(_xlfn.FORMULATEXT(B22),",",", ") -> =QS.CURVE.GET(Loan_Context, "ESTR")
A25: 7.1 Fair-rate request 0 | B25: {=_xll.QS.REQUEST.FAIR.RATE(0)} | C25: Returns one requested segment's scalar; earlier segments are bootstrapped first.
A26: =SUBSTITUTE(_xlfn.FORMULATEXT(B25),",",", ") -> =QS.REQUEST.FAIR.RATE(0)
A28: 7.2 Fair-rate request 1 | B28: {=_xll.QS.REQUEST.FAIR.RATE(1)} | C28: Returns one requested segment's scalar; earlier segments are bootstrapped first.
A29: =SUBSTITUTE(_xlfn.FORMULATEXT(B28),",",", ") -> =QS.REQUEST.FAIR.RATE(1)
A31: 7.3 Fair-rate request 2 | B31: {=_xll.QS.REQUEST.FAIR.RATE(2)} | C31: Returns one requested segment's scalar; earlier segments are bootstrapped first.
A32: =SUBSTITUTE(_xlfn.FORMULATEXT(B31),",",", ") -> =QS.REQUEST.FAIR.RATE(2)
A34: 01. French
A35: Edit these case inputs →
A37: 1. Define this instrument | B37: {=_xll.QS.INSTRUMENT.LOAN("Loan.C01.Instrument",Loan_Start,Loan_Maturity,Loan_Currency,Loan_Notional,Loan_C01_Rate,Loan_C01_Index,Loan_C01_Repayment,Loan_Frequency,Loan_DayCounter,,)} | C37: Baseline monthly amortization.
A38: =SUBSTITUTE(_xlfn.FORMULATEXT(B37),",",", ") -> =QS.INSTRUMENT.LOAN("Loan.C01.Instrument", Loan_Start, Loan_Maturity, Loan_Currency, Loan_Notional, Loan_C01_Rate, Loan_C01_Index, Loan_C01_Repayment, Loan_Frequency, Loan_DayCounter, , )
A40: 2. Create this position | B40: {=_xll.QS.TRADE.CREATE("Loan.C01.Trade",Loan_C01_Instrument,Loan_ValuationDate,Loan_Side)} | C40: The contractual principal stays in the instrument.
A41: =SUBSTITUTE(_xlfn.FORMULATEXT(B40),",",", ") -> =QS.TRADE.CREATE("Loan.C01.Trade", Loan_C01_Instrument, Loan_ValuationDate, Loan_Side)
A43: 3. Select explicit pricer | B43: =IF(Loan_C01_Discount="FUNDING",Loan_FundingPricer,Loan_RiskFreePricer) | C43: The case's discount choice selects an existing policy-configured pricer.
A44: =SUBSTITUTE(_xlfn.FORMULATEXT(B43),",",", ") -> =IF(Loan_C01_Discount="FUNDING", Loan_FundingPricer, Loan_RiskFreePricer)
A46: 4. Evaluate value and tables | B46: {=_xll.QS.EVALUATE("Loan.C01.Result",Loan_C01_Pricer,Loan_C01_Trade,Loan_Context,Loan_Requests)} | C46: Future receipt PV excludes the original principal advance.
A47: =SUBSTITUTE(_xlfn.FORMULATEXT(B46),",",", ") -> =QS.EVALUATE("Loan.C01.Result", Loan_C01_Pricer, Loan_C01_Trade, Loan_Context, Loan_Requests)
A49: 5.1 Solve segment 0 | B49: {=_xll.QS.EVALUATE("Loan.C01.Fair0",Loan_C01_Pricer,Loan_C01_Trade,Loan_Context,Loan_Request0)} | C49: Repay remaining principal at each prefix end, lock earlier solved rates, then extend.
A50: =SUBSTITUTE(_xlfn.FORMULATEXT(B49),",",", ") -> =QS.EVALUATE("Loan.C01.Fair0", Loan_C01_Pricer, Loan_C01_Trade, Loan_Context, Loan_Request0)
A54: 02. Bullet
A55: Edit these case inputs →
A57: 1. Define this instrument | B57: {=_xll.QS.INSTRUMENT.LOAN("Loan.C02.Instrument",Loan_Start,Loan_Maturity,Loan_Currency,Loan_Notional,Loan_C02_Rate,Loan_C02_Index,Loan_C02_Repayment,Loan_Frequency,Loan_DayCounter,,)} | C57: Repay all principal at maturity.
A58: =SUBSTITUTE(_xlfn.FORMULATEXT(B57),",",", ") -> =QS.INSTRUMENT.LOAN("Loan.C02.Instrument", Loan_Start, Loan_Maturity, Loan_Currency, Loan_Notional, Loan_C02_Rate, Loan_C02_Index, Loan_C02_Repayment, Loan_Frequency, Loan_DayCounter, , )
A60: 2. Create this position | B60: {=_xll.QS.TRADE.CREATE("Loan.C02.Trade",Loan_C02_Instrument,Loan_ValuationDate,Loan_Side)} | C60: The contractual principal stays in the instrument.
A61: =SUBSTITUTE(_xlfn.FORMULATEXT(B60),",",", ") -> =QS.TRADE.CREATE("Loan.C02.Trade", Loan_C02_Instrument, Loan_ValuationDate, Loan_Side)
...

Sheet 5 Results
A1: Compare the loan results
A2: PV is future receipt value in EUR; net origination value subtracts principal. Fair-rate columns are annual decimal coupon / spread levels. Blank means that segment does not exist.
A4: ← Start Here | H4: Next → 6 Cashflows
A6: Case | B6: Receipt PV (EUR) | C6: PV less advance | D6: Fair segment 0 | E6: Fair segment 1 | F6: Fair segment 2 | G6: Edit inputs | H6: Read build
A7: French | B7: {=_xll.QS.RESULT.VALUE(Loan_C01_Result)} | C7: =Loan_C01_PV-Loan_Notional | D7: {=_xll.QS.RESULT.FAIR.RATE(Loan_C01_Fair0)} | G7: Edit → | H7: Build →
A8: Bullet | B8: {=_xll.QS.RESULT.VALUE(Loan_C02_Result)} | C8: =Loan_C02_PV-Loan_Notional | D8: {=_xll.QS.RESULT.FAIR.RATE(Loan_C02_Fair0)} | G8: Edit → | H8: Build →
A9: 25% balloon | B9: {=_xll.QS.RESULT.VALUE(Loan_C03_Result)} | C9: =Loan_C03_PV-Loan_Notional | D9: {=_xll.QS.RESULT.FAIR.RATE(Loan_C03_Fair0)} | G9: Edit → | H9: Build →
A10: Floating | B10: {=_xll.QS.RESULT.VALUE(Loan_C04_Result)} | C10: =Loan_C04_PV-Loan_Notional | D10: {=_xll.QS.RESULT.FAIR.RATE(Loan_C04_Fair0)} | G10: Edit → | H10: Build →
A11: 5-year introductory fixed | B11: {=_xll.QS.RESULT.VALUE(Loan_C05_Result)} | C11: =Loan_C05_PV-Loan_Notional | D11: {=_xll.QS.RESULT.FAIR.RATE(Loan_C05_Fair0)} | E11: {=_xll.QS.RESULT.FAIR.RATE(Loan_C05_Fair1)} | G11: Edit → | H11: Build →
A12: Bounded floating | B12: {=_xll.QS.RESULT.VALUE(Loan_C06_Result)} | C12: =Loan_C06_PV-Loan_Notional | D12: Bounded: n/a | G12: Edit → | H12: Build →
A13: 15% annual CPR | B13: {=_xll.QS.RESULT.VALUE(Loan_C07_Result)} | C13: =Loan_C07_PV-Loan_Notional | D13: {=_xll.QS.RESULT.FAIR.RATE(Loan_C07_Fair0)} | G13: Edit → | H13: Build →
A14: Borrower credit | B14: {=_xll.QS.RESULT.VALUE(Loan_C08_Result)} | C14: =Loan_C08_PV-Loan_Notional | D14: {=_xll.QS.RESULT.FAIR.RATE(Loan_C08_Fair0)} | G14: Edit → | H14: Build →
A15: Funded fixed | B15: {=_xll.QS.RESULT.VALUE(Loan_C09_Result)} | C15: =Loan_C09_PV-Loan_Notional | D15: {=_xll.QS.RESULT.FAIR.RATE(Loan_C09_Fair0)} | G15: Edit → | H15: Build →
A16: Funded floating | B16: {=_xll.QS.RESULT.VALUE(Loan_C10_Result)} | C16: =Loan_C10_PV-Loan_Notional | D16: {=_xll.QS.RESULT.FAIR.RATE(Loan_C10_Fair0)} | G16: Edit → | H16: Build →
A17: Stepped fixed | B17: {=_xll.QS.RESULT.VALUE(Loan_C11_Result)} | C17: =Loan_C11_PV-Loan_Notional | D17: {=_xll.QS.RESULT.FAIR.RATE(Loan_C11_Fair0)} | E17: {=_xll.QS.RESULT.FAIR.RATE(Loan_C11_Fair1)} | F17: {=_xll.QS.RESULT.FAIR.RATE(Loan_C11_Fair2)} | G17: Edit → | H17: Build →
A18: Stepped then floating | B18: {=_xll.QS.RESULT.VALUE(Loan_C12_Result)} | C18: =Loan_C12_PV-Loan_Notional | D18: {=_xll.QS.RESULT.FAIR.RATE(Loan_C12_Fair0)} | E18: {=_xll.QS.RESULT.FAIR.RATE(Loan_C12_Fair1)} | F18: {=_xll.QS.RESULT.FAIR.RATE(Loan_C12_Fair2)} | G18: Edit → | H18: Build →
A22: Inspect one case | B22: French | C22: Choose a case, then open Cashflows or Risk. Both detail sheets follow this selection.
A26: FairRate(index) returns one scalar. For mixed or stepped loans, earlier rate segments are solved and fixed before the selected segment is solved. The original agreement remains unchanged. Bounded coupons have no fair-rate output.

Sheet 6 Cashflows
A1: Selected loan · expected receipts
A2: Signed, undiscounted receipts and payments in each row's currency. Loan legs 0 / 1 / 2 are scheduled receipts / prepayment / recovery.
A4: ← Start Here | I4: Next → 7 Risk
A6: Selected case | B6: =Loan_SelectedCase | C6: Change case →
A7: {=_xll.QS.RESULT.CASHFLOWS(Loan_SelectedResult)}

Sheet 7 Risk
A1: Selected loan · market risk
A2: Raw value derivatives per unit input. Multiply a decimal-rate derivative by 0.0001 to estimate a +1 bp move. Preserve each factor's units.
A4: ← Start Here | C4: Next → 8 Layouts
A6: Selected case | B6: =Loan_SelectedCase | C6: Change case →
A7: {=_xll.QS.RESULT.SENSITIVITIES(Loan_SelectedResult)}

Sheet 8 Layouts
A1: Table layout · transpose and headers
A2: The same small ESTR curve table is shown four ways. Header removal happens before transposition. All other report tables accept the same flags.
A4: ← Start Here
A6: Default · rows with headers
A7: {=_xll.QS.CURVE.TABLE(Loan_EstrCurve,"Simple","Annual",FALSE,TRUE)}
A16: Rows without headers
A17: {=_xll.QS.CURVE.TABLE(Loan_EstrCurve,"Simple","Annual",FALSE,FALSE)}
A26: Transposed with headers
A27: {=_xll.QS.CURVE.TABLE(Loan_EstrCurve,"Simple","Annual",TRUE,TRUE)}
A36: Transposed without headers
A37: {=_xll.QS.CURVE.TABLE(Loan_EstrCurve,"Simple","Annual",TRUE,FALSE)}
